[13/Jun/2020 15:49:40] ERROR [django.request:228] Internal Server Error: /clase/activar/2/
Traceback (most recent call last):
  File "/home/luislaredov/.virtualenvs/django2/lib/python3.6/site-packages/django/core/handlers/exception.py", line 34, in inner
    response = get_response(request)
  File "/home/luislaredov/.virtualenvs/django2/lib/python3.6/site-packages/django/core/handlers/base.py", line 115, in _get_response
    response = self.process_exception_by_middleware(e, request)
  File "/home/luislaredov/.virtualenvs/django2/lib/python3.6/site-packages/django/core/handlers/base.py", line 113, in _get_response
    response = wrapped_callback(request, *callback_args, **callback_kwargs)
TypeError: EditarClase() got an unexpected keyword argument 'clase_id'
[13/Jun/2020 15:59:16] WARNING [django.request:228] Not Found: /clase/imagen/actualizar/2/
[13/Jun/2020 16:27:38] ERROR [django.request:228] Internal Server Error: /clase/visualizar/1/0/
Traceback (most recent call last):
  File "/home/luislaredov/.virtualenvs/django2/lib/python3.6/site-packages/django/core/handlers/exception.py", line 34, in inner
    response = get_response(request)
  File "/home/luislaredov/.virtualenvs/django2/lib/python3.6/site-packages/django/core/handlers/base.py", line 115, in _get_response
    response = self.process_exception_by_middleware(e, request)
  File "/home/luislaredov/.virtualenvs/django2/lib/python3.6/site-packages/django/core/handlers/base.py", line 113, in _get_response
    response = wrapped_callback(request, *callback_args, **callback_kwargs)
TypeError: VisualizarClase() got multiple values for argument 'clase_id'
[13/Jun/2020 16:30:25] ERROR [django.request:228] Internal Server Error: /clase/visualizar/1/0/
Traceback (most recent call last):
  File "/home/luislaredov/.virtualenvs/django2/lib/python3.6/site-packages/django/core/handlers/exception.py", line 34, in inner
    response = get_response(request)
  File "/home/luislaredov/.virtualenvs/django2/lib/python3.6/site-packages/django/core/handlers/base.py", line 115, in _get_response
    response = self.process_exception_by_middleware(e, request)
  File "/home/luislaredov/.virtualenvs/django2/lib/python3.6/site-packages/django/core/handlers/base.py", line 113, in _get_response
    response = wrapped_callback(request, *callback_args, **callback_kwargs)
TypeError: VisualizarClase() got multiple values for argument 'clase_id'
[13/Jun/2020 16:32:56] ERROR [django.request:228] Internal Server Error: /clase/visualizar/1/0/
Traceback (most recent call last):
  File "/home/luislaredov/.virtualenvs/django2/lib/python3.6/site-packages/django/core/handlers/exception.py", line 34, in inner
    response = get_response(request)
  File "/home/luislaredov/.virtualenvs/django2/lib/python3.6/site-packages/django/core/handlers/base.py", line 115, in _get_response
    response = self.process_exception_by_middleware(e, request)
  File "/home/luislaredov/.virtualenvs/django2/lib/python3.6/site-packages/django/core/handlers/base.py", line 113, in _get_response
    response = wrapped_callback(request, *callback_args, **callback_kwargs)
TypeError: VisualizarClase() got multiple values for argument 'clase_id'
[13/Jun/2020 16:33:58] ERROR [django.request:228] Internal Server Error: /clase/visualizar/1/0/
Traceback (most recent call last):
  File "/home/luislaredov/.virtualenvs/django2/lib/python3.6/site-packages/django/core/handlers/exception.py", line 34, in inner
    response = get_response(request)
  File "/home/luislaredov/.virtualenvs/django2/lib/python3.6/site-packages/django/core/handlers/base.py", line 115, in _get_response
    response = self.process_exception_by_middleware(e, request)
  File "/home/luislaredov/.virtualenvs/django2/lib/python3.6/site-packages/django/core/handlers/base.py", line 113, in _get_response
    response = wrapped_callback(request, *callback_args, **callback_kwargs)
  File "/home/luislaredov/pixkal/pixkal2/views.py", line 665, in VisualizarClase
    items = ClaseItem.objects.get(clase=clase)
  File "/home/luislaredov/.virtualenvs/django2/lib/python3.6/site-packages/django/db/models/manager.py", line 82, in manager_method
    return getattr(self.get_queryset(), name)(*args, **kwargs)
  File "/home/luislaredov/.virtualenvs/django2/lib/python3.6/site-packages/django/db/models/query.py", line 417, in get
    self.model._meta.object_name
pixkal2.models.ClaseItem.DoesNotExist: ClaseItem matching query does not exist.
[13/Jun/2020 16:34:31] ERROR [django.request:228] Internal Server Error: /clase/visualizar/1/0/
Traceback (most recent call last):
  File "/home/luislaredov/.virtualenvs/django2/lib/python3.6/site-packages/django/core/handlers/exception.py", line 34, in inner
    response = get_response(request)
  File "/home/luislaredov/.virtualenvs/django2/lib/python3.6/site-packages/django/core/handlers/base.py", line 115, in _get_response
    response = self.process_exception_by_middleware(e, request)
  File "/home/luislaredov/.virtualenvs/django2/lib/python3.6/site-packages/django/core/handlers/base.py", line 113, in _get_response
    response = wrapped_callback(request, *callback_args, **callback_kwargs)
  File "/home/luislaredov/pixkal/pixkal2/views.py", line 664, in VisualizarClase
    items = ClaseItem.objects.get(clase=clase_id)
  File "/home/luislaredov/.virtualenvs/django2/lib/python3.6/site-packages/django/db/models/manager.py", line 82, in manager_method
    return getattr(self.get_queryset(), name)(*args, **kwargs)
  File "/home/luislaredov/.virtualenvs/django2/lib/python3.6/site-packages/django/db/models/query.py", line 417, in get
    self.model._meta.object_name
pixkal2.models.ClaseItem.DoesNotExist: ClaseItem matching query does not exist.
[13/Jun/2020 16:35:00] ERROR [django.request:228] Internal Server Error: /clase/visualizar/2/0/
Traceback (most recent call last):
  File "/home/luislaredov/.virtualenvs/django2/lib/python3.6/site-packages/django/core/handlers/exception.py", line 34, in inner
    response = get_response(request)
  File "/home/luislaredov/.virtualenvs/django2/lib/python3.6/site-packages/django/core/handlers/base.py", line 115, in _get_response
    response = self.process_exception_by_middleware(e, request)
  File "/home/luislaredov/.virtualenvs/django2/lib/python3.6/site-packages/django/core/handlers/base.py", line 113, in _get_response
    response = wrapped_callback(request, *callback_args, **callback_kwargs)
  File "/home/luislaredov/pixkal/pixkal2/views.py", line 664, in VisualizarClase
    items = ClaseItem.objects.get(clase=clase_id)
  File "/home/luislaredov/.virtualenvs/django2/lib/python3.6/site-packages/django/db/models/manager.py", line 82, in manager_method
    return getattr(self.get_queryset(), name)(*args, **kwargs)
  File "/home/luislaredov/.virtualenvs/django2/lib/python3.6/site-packages/django/db/models/query.py", line 422, in get
    num if not limit or num < limit else 'more than %s' % (limit - 1),
pixkal2.models.ClaseItem.MultipleObjectsReturned: get() returned more than one ClaseItem -- it returned 3!
[13/Jun/2020 16:35:56] ERROR [django.request:228] Internal Server Error: /clase/visualizar/2/0/
Traceback (most recent call last):
  File "/home/luislaredov/.virtualenvs/django2/lib/python3.6/site-packages/django/core/handlers/exception.py", line 34, in inner
    response = get_response(request)
  File "/home/luislaredov/.virtualenvs/django2/lib/python3.6/site-packages/django/core/handlers/base.py", line 115, in _get_response
    response = self.process_exception_by_middleware(e, request)
  File "/home/luislaredov/.virtualenvs/django2/lib/python3.6/site-packages/django/core/handlers/base.py", line 113, in _get_response
    response = wrapped_callback(request, *callback_args, **callback_kwargs)
  File "/home/luislaredov/pixkal/pixkal2/views.py", line 665, in VisualizarClase
    return render('pixkal2/visualizarclase.html', {'items': items })
  File "/home/luislaredov/.virtualenvs/django2/lib/python3.6/site-packages/django/shortcuts.py", line 19, in render
    content = loader.render_to_string(template_name, context, request, using=using)
  File "/home/luislaredov/.virtualenvs/django2/lib/python3.6/site-packages/django/template/loader.py", line 61, in render_to_string
    template = get_template(template_name, using=using)
  File "/home/luislaredov/.virtualenvs/django2/lib/python3.6/site-packages/django/template/loader.py", line 15, in get_template
    return engine.get_template(template_name)
  File "/home/luislaredov/.virtualenvs/django2/lib/python3.6/site-packages/django/template/backends/django.py", line 34, in get_template
    return Template(self.engine.get_template(template_name), self)
  File "/home/luislaredov/.virtualenvs/django2/lib/python3.6/site-packages/django/template/engine.py", line 143, in get_template
    template, origin = self.find_template(template_name)
  File "/home/luislaredov/.virtualenvs/django2/lib/python3.6/site-packages/django/template/engine.py", line 125, in find_template
    template = loader.get_template(name, skip=skip)
  File "/home/luislaredov/.virtualenvs/django2/lib/python3.6/site-packages/django/template/loaders/base.py", line 18, in get_template
    for origin in self.get_template_sources(template_name):
  File "/home/luislaredov/.virtualenvs/django2/lib/python3.6/site-packages/django/template/loaders/filesystem.py", line 36, in get_template_sources
    name = safe_join(template_dir, template_name)
  File "/home/luislaredov/.virtualenvs/django2/lib/python3.6/site-packages/django/utils/_os.py", line 17, in safe_join
    final_path = abspath(join(base, *paths))
  File "/home/luislaredov/.virtualenvs/django2/lib/python3.6/posixpath.py", line 94, in join
    genericpath._check_arg_types('join', a, *p)
  File "/home/luislaredov/.virtualenvs/django2/lib/python3.6/genericpath.py", line 149, in _check_arg_types
    (funcname, s.__class__.__name__)) from None
TypeError: join() argument must be str or bytes, not 'dict'
[13/Jun/2020 17:22:28] ERROR [django.request:228] Internal Server Error: /clase/visualizar/2/0/
Traceback (most recent call last):
  File "/home/luislaredov/.virtualenvs/django2/lib/python3.6/site-packages/django/core/handlers/exception.py", line 34, in inner
    response = get_response(request)
  File "/home/luislaredov/.virtualenvs/django2/lib/python3.6/site-packages/django/core/handlers/base.py", line 115, in _get_response
    response = self.process_exception_by_middleware(e, request)
  File "/home/luislaredov/.virtualenvs/django2/lib/python3.6/site-packages/django/core/handlers/base.py", line 113, in _get_response
    response = wrapped_callback(request, *callback_args, **callback_kwargs)
  File "/home/luislaredov/pixkal/pixkal2/views.py", line 665, in VisualizarClase
    item = items[orden]
  File "/home/luislaredov/.virtualenvs/django2/lib/python3.6/site-packages/django/db/models/query.py", line 288, in __getitem__
    % type(k).__name__
TypeError: QuerySet indices must be integers or slices, not str.
[13/Jun/2020 18:05:21] ERROR [django.request:228] Internal Server Error: /clase/visualizar/1/1/
Traceback (most recent call last):
  File "/home/luislaredov/.virtualenvs/django2/lib/python3.6/site-packages/django/core/handlers/exception.py", line 34, in inner
    response = get_response(request)
  File "/home/luislaredov/.virtualenvs/django2/lib/python3.6/site-packages/django/core/handlers/base.py", line 115, in _get_response
    response = self.process_exception_by_middleware(e, request)
  File "/home/luislaredov/.virtualenvs/django2/lib/python3.6/site-packages/django/core/handlers/base.py", line 113, in _get_response
    response = wrapped_callback(request, *callback_args, **callback_kwargs)
  File "/home/luislaredov/pixkal/pixkal2/views.py", line 665, in VisualizarClase
    item = items[int(orden)]
  File "/home/luislaredov/.virtualenvs/django2/lib/python3.6/site-packages/django/db/models/query.py", line 314, in __getitem__
    return qs._result_cache[0]
IndexError: list index out of range
[15/Jun/2020 17:51:46] WARNING [django.request:228] Not Found: /favicon.ico
[15/Jun/2020 17:51:57] ERROR [django.request:228] Internal Server Error: /admin/pixkal2/clase/
Traceback (most recent call last):
  File "/home/luislaredov/.virtualenvs/django2/lib/python3.6/site-packages/django/db/backends/utils.py", line 86, in _execute
    return self.cursor.execute(sql, params)
  File "/home/luislaredov/.virtualenvs/django2/lib/python3.6/site-packages/django/db/backends/mysql/base.py", line 74, in execute
    return self.cursor.execute(query, args)
  File "/home/luislaredov/.virtualenvs/django2/lib/python3.6/site-packages/MySQLdb/cursors.py", line 209, in execute
    res = self._query(query)
  File "/home/luislaredov/.virtualenvs/django2/lib/python3.6/site-packages/MySQLdb/cursors.py", line 315, in _query
    db.query(q)
  File "/home/luislaredov/.virtualenvs/django2/lib/python3.6/site-packages/MySQLdb/connections.py", line 239, in query
    _mysql.connection.query(self, query)
MySQLdb._exceptions.OperationalError: (1054, "Unknown column 'pixkal2_clase.bandera_marcador' in 'field list'")

The above exception was the direct cause of the following exception:

Traceback (most recent call last):
  File "/home/luislaredov/.virtualenvs/django2/lib/python3.6/site-packages/django/core/handlers/exception.py", line 34, in inner
    response = get_response(request)
  File "/home/luislaredov/.virtualenvs/django2/lib/python3.6/site-packages/django/core/handlers/base.py", line 115, in _get_response
    response = self.process_exception_by_middleware(e, request)
  File "/home/luislaredov/.virtualenvs/django2/lib/python3.6/site-packages/django/core/handlers/base.py", line 113, in _get_response
    response = wrapped_callback(request, *callback_args, **callback_kwargs)
  File "/home/luislaredov/.virtualenvs/django2/lib/python3.6/site-packages/django/contrib/admin/options.py", line 607, in wrapper
    return self.admin_site.admin_view(view)(*args, **kwargs)
  File "/home/luislaredov/.virtualenvs/django2/lib/python3.6/site-packages/django/utils/decorators.py", line 130, in _wrapped_view
    response = view_func(request, *args, **kwargs)
  File "/home/luislaredov/.virtualenvs/django2/lib/python3.6/site-packages/django/views/decorators/cache.py", line 44, in _wrapped_view_func
    response = view_func(request, *args, **kwargs)
  File "/home/luislaredov/.virtualenvs/django2/lib/python3.6/site-packages/django/contrib/admin/sites.py", line 231, in inner
    return view(request, *args, **kwargs)
  File "/home/luislaredov/.virtualenvs/django2/lib/python3.6/site-packages/django/utils/decorators.py", line 43, in _wrapper
    return bound_method(*args, **kwargs)
  File "/home/luislaredov/.virtualenvs/django2/lib/python3.6/site-packages/django/utils/decorators.py", line 130, in _wrapped_view
    response = view_func(request, *args, **kwargs)
  File "/home/luislaredov/.virtualenvs/django2/lib/python3.6/site-packages/django/contrib/admin/options.py", line 1796, in changelist_view
    'selection_note': _('0 of %(cnt)s selected') % {'cnt': len(cl.result_list)},
  File "/home/luislaredov/.virtualenvs/django2/lib/python3.6/site-packages/django/db/models/query.py", line 258, in __len__
    self._fetch_all()
  File "/home/luislaredov/.virtualenvs/django2/lib/python3.6/site-packages/django/db/models/query.py", line 1261, in _fetch_all
    self._result_cache = list(self._iterable_class(self))
  File "/home/luislaredov/.virtualenvs/django2/lib/python3.6/site-packages/django/db/models/query.py", line 57, in __iter__
    results = compiler.execute_sql(chunked_fetch=self.chunked_fetch, chunk_size=self.chunk_size)
  File "/home/luislaredov/.virtualenvs/django2/lib/python3.6/site-packages/django/db/models/sql/compiler.py", line 1151, in execute_sql
    cursor.execute(sql, params)
  File "/home/luislaredov/.virtualenvs/django2/lib/python3.6/site-packages/django/db/backends/utils.py", line 100, in execute
    return super().execute(sql, params)
  File "/home/luislaredov/.virtualenvs/django2/lib/python3.6/site-packages/django/db/backends/utils.py", line 68, in execute
    return self._execute_with_wrappers(sql, params, many=False, executor=self._execute)
  File "/home/luislaredov/.virtualenvs/django2/lib/python3.6/site-packages/django/db/backends/utils.py", line 77, in _execute_with_wrappers
    return executor(sql, params, many, context)
  File "/home/luislaredov/.virtualenvs/django2/lib/python3.6/site-packages/django/db/backends/utils.py", line 86, in _execute
    return self.cursor.execute(sql, params)
  File "/home/luislaredov/.virtualenvs/django2/lib/python3.6/site-packages/django/db/utils.py", line 90, in __exit__
    raise dj_exc_value.with_traceback(traceback) from exc_value
  File "/home/luislaredov/.virtualenvs/django2/lib/python3.6/site-packages/django/db/backends/utils.py", line 86, in _execute
    return self.cursor.execute(sql, params)
  File "/home/luislaredov/.virtualenvs/django2/lib/python3.6/site-packages/django/db/backends/mysql/base.py", line 74, in execute
    return self.cursor.execute(query, args)
  File "/home/luislaredov/.virtualenvs/django2/lib/python3.6/site-packages/MySQLdb/cursors.py", line 209, in execute
    res = self._query(query)
  File "/home/luislaredov/.virtualenvs/django2/lib/python3.6/site-packages/MySQLdb/cursors.py", line 315, in _query
    db.query(q)
  File "/home/luislaredov/.virtualenvs/django2/lib/python3.6/site-packages/MySQLdb/connections.py", line 239, in query
    _mysql.connection.query(self, query)
django.db.utils.OperationalError: (1054, "Unknown column 'pixkal2_clase.bandera_marcador' in 'field list'")
[15/Jun/2020 17:59:19] ERROR [django.request:228] Internal Server Error: /admin/pixkal2/clase/
Traceback (most recent call last):
  File "/home/luislaredov/.virtualenvs/django2/lib/python3.6/site-packages/django/db/backends/utils.py", line 86, in _execute
    return self.cursor.execute(sql, params)
  File "/home/luislaredov/.virtualenvs/django2/lib/python3.6/site-packages/django/db/backends/mysql/base.py", line 74, in execute
    return self.cursor.execute(query, args)
  File "/home/luislaredov/.virtualenvs/django2/lib/python3.6/site-packages/MySQLdb/cursors.py", line 209, in execute
    res = self._query(query)
  File "/home/luislaredov/.virtualenvs/django2/lib/python3.6/site-packages/MySQLdb/cursors.py", line 315, in _query
    db.query(q)
  File "/home/luislaredov/.virtualenvs/django2/lib/python3.6/site-packages/MySQLdb/connections.py", line 239, in query
    _mysql.connection.query(self, query)
MySQLdb._exceptions.OperationalError: (1054, "Unknown column 'pixkal2_clase.bandera_marcador' in 'field list'")

The above exception was the direct cause of the following exception:

Traceback (most recent call last):
  File "/home/luislaredov/.virtualenvs/django2/lib/python3.6/site-packages/django/core/handlers/exception.py", line 34, in inner
    response = get_response(request)
  File "/home/luislaredov/.virtualenvs/django2/lib/python3.6/site-packages/django/core/handlers/base.py", line 115, in _get_response
    response = self.process_exception_by_middleware(e, request)
  File "/home/luislaredov/.virtualenvs/django2/lib/python3.6/site-packages/django/core/handlers/base.py", line 113, in _get_response
    response = wrapped_callback(request, *callback_args, **callback_kwargs)
  File "/home/luislaredov/.virtualenvs/django2/lib/python3.6/site-packages/django/contrib/admin/options.py", line 607, in wrapper
    return self.admin_site.admin_view(view)(*args, **kwargs)
  File "/home/luislaredov/.virtualenvs/django2/lib/python3.6/site-packages/django/utils/decorators.py", line 130, in _wrapped_view
    response = view_func(request, *args, **kwargs)
  File "/home/luislaredov/.virtualenvs/django2/lib/python3.6/site-packages/django/views/decorators/cache.py", line 44, in _wrapped_view_func
    response = view_func(request, *args, **kwargs)
  File "/home/luislaredov/.virtualenvs/django2/lib/python3.6/site-packages/django/contrib/admin/sites.py", line 231, in inner
    return view(request, *args, **kwargs)
  File "/home/luislaredov/.virtualenvs/django2/lib/python3.6/site-packages/django/utils/decorators.py", line 43, in _wrapper
    return bound_method(*args, **kwargs)
  File "/home/luislaredov/.virtualenvs/django2/lib/python3.6/site-packages/django/utils/decorators.py", line 130, in _wrapped_view
    response = view_func(request, *args, **kwargs)
  File "/home/luislaredov/.virtualenvs/django2/lib/python3.6/site-packages/django/contrib/admin/options.py", line 1796, in changelist_view
    'selection_note': _('0 of %(cnt)s selected') % {'cnt': len(cl.result_list)},
  File "/home/luislaredov/.virtualenvs/django2/lib/python3.6/site-packages/django/db/models/query.py", line 258, in __len__
    self._fetch_all()
  File "/home/luislaredov/.virtualenvs/django2/lib/python3.6/site-packages/django/db/models/query.py", line 1261, in _fetch_all
    self._result_cache = list(self._iterable_class(self))
  File "/home/luislaredov/.virtualenvs/django2/lib/python3.6/site-packages/django/db/models/query.py", line 57, in __iter__
    results = compiler.execute_sql(chunked_fetch=self.chunked_fetch, chunk_size=self.chunk_size)
  File "/home/luislaredov/.virtualenvs/django2/lib/python3.6/site-packages/django/db/models/sql/compiler.py", line 1151, in execute_sql
    cursor.execute(sql, params)
  File "/home/luislaredov/.virtualenvs/django2/lib/python3.6/site-packages/django/db/backends/utils.py", line 100, in execute
    return super().execute(sql, params)
  File "/home/luislaredov/.virtualenvs/django2/lib/python3.6/site-packages/django/db/backends/utils.py", line 68, in execute
    return self._execute_with_wrappers(sql, params, many=False, executor=self._execute)
  File "/home/luislaredov/.virtualenvs/django2/lib/python3.6/site-packages/django/db/backends/utils.py", line 77, in _execute_with_wrappers
    return executor(sql, params, many, context)
  File "/home/luislaredov/.virtualenvs/django2/lib/python3.6/site-packages/django/db/backends/utils.py", line 86, in _execute
    return self.cursor.execute(sql, params)
  File "/home/luislaredov/.virtualenvs/django2/lib/python3.6/site-packages/django/db/utils.py", line 90, in __exit__
    raise dj_exc_value.with_traceback(traceback) from exc_value
  File "/home/luislaredov/.virtualenvs/django2/lib/python3.6/site-packages/django/db/backends/utils.py", line 86, in _execute
    return self.cursor.execute(sql, params)
  File "/home/luislaredov/.virtualenvs/django2/lib/python3.6/site-packages/django/db/backends/mysql/base.py", line 74, in execute
    return self.cursor.execute(query, args)
  File "/home/luislaredov/.virtualenvs/django2/lib/python3.6/site-packages/MySQLdb/cursors.py", line 209, in execute
    res = self._query(query)
  File "/home/luislaredov/.virtualenvs/django2/lib/python3.6/site-packages/MySQLdb/cursors.py", line 315, in _query
    db.query(q)
  File "/home/luislaredov/.virtualenvs/django2/lib/python3.6/site-packages/MySQLdb/connections.py", line 239, in query
    _mysql.connection.query(self, query)
django.db.utils.OperationalError: (1054, "Unknown column 'pixkal2_clase.bandera_marcador' in 'field list'")
[15/Jun/2020 19:14:28] WARNING [django.request:228] Not Found: /pixkal2/clase/registrar/
[15/Jun/2020 19:16:30] WARNING [django.request:228] Not Found: /pixkal2/clase/registrar/
[15/Jun/2020 19:18:40] WARNING [django.request:228] Not Found: /pixkal2/clase/registrar/
[15/Jun/2020 19:21:59] WARNING [django.request:228] Not Found: /pixkal2/clase/registrar/
[15/Jun/2020 19:23:09] WARNING [django.request:228] Not Found: /pixkal2/perfil/actualizar/
[15/Jun/2020 19:27:50] ERROR [django.request:228] Internal Server Error: /clase/visualizar/1/3/
Traceback (most recent call last):
  File "/home/luislaredov/.virtualenvs/django2/lib/python3.6/site-packages/django/core/handlers/exception.py", line 34, in inner
    response = get_response(request)
  File "/home/luislaredov/.virtualenvs/django2/lib/python3.6/site-packages/django/core/handlers/base.py", line 115, in _get_response
    response = self.process_exception_by_middleware(e, request)
  File "/home/luislaredov/.virtualenvs/django2/lib/python3.6/site-packages/django/core/handlers/base.py", line 113, in _get_response
    response = wrapped_callback(request, *callback_args, **callback_kwargs)
  File "/home/luislaredov/pixkal/pixkal2/views.py", line 665, in VisualizarClase
    item = items[int(orden)]
  File "/home/luislaredov/.virtualenvs/django2/lib/python3.6/site-packages/django/db/models/query.py", line 314, in __getitem__
    return qs._result_cache[0]
IndexError: list index out of range
[15/Jun/2020 19:32:04] ERROR [django.request:228] Internal Server Error: /clase/visualizar/1/0/
Traceback (most recent call last):
  File "/home/luislaredov/.virtualenvs/django2/lib/python3.6/site-packages/django/core/handlers/exception.py", line 34, in inner
    response = get_response(request)
  File "/home/luislaredov/.virtualenvs/django2/lib/python3.6/site-packages/django/core/handlers/base.py", line 115, in _get_response
    response = self.process_exception_by_middleware(e, request)
  File "/home/luislaredov/.virtualenvs/django2/lib/python3.6/site-packages/django/core/handlers/base.py", line 113, in _get_response
    response = wrapped_callback(request, *callback_args, **callback_kwargs)
  File "/home/luislaredov/pixkal/pixkal2/views.py", line 668, in VisualizarClase
    return render(request, 'pixkal2/visualizarclase.html', {'item': item,'orden': orden,'clase_id':clase_id,'clase':principal_clase })
  File "/home/luislaredov/.virtualenvs/django2/lib/python3.6/site-packages/django/shortcuts.py", line 19, in render
    content = loader.render_to_string(template_name, context, request, using=using)
  File "/home/luislaredov/.virtualenvs/django2/lib/python3.6/site-packages/django/template/loader.py", line 61, in render_to_string
    template = get_template(template_name, using=using)
  File "/home/luislaredov/.virtualenvs/django2/lib/python3.6/site-packages/django/template/loader.py", line 15, in get_template
    return engine.get_template(template_name)
  File "/home/luislaredov/.virtualenvs/django2/lib/python3.6/site-packages/django/template/backends/django.py", line 34, in get_template
    return Template(self.engine.get_template(template_name), self)
  File "/home/luislaredov/.virtualenvs/django2/lib/python3.6/site-packages/django/template/engine.py", line 143, in get_template
    template, origin = self.find_template(template_name)
  File "/home/luislaredov/.virtualenvs/django2/lib/python3.6/site-packages/django/template/engine.py", line 125, in find_template
    template = loader.get_template(name, skip=skip)
  File "/home/luislaredov/.virtualenvs/django2/lib/python3.6/site-packages/django/template/loaders/base.py", line 30, in get_template
    contents, origin, origin.template_name, self.engine,
  File "/home/luislaredov/.virtualenvs/django2/lib/python3.6/site-packages/django/template/base.py", line 156, in __init__
    self.nodelist = self.compile_nodelist()
  File "/home/luislaredov/.virtualenvs/django2/lib/python3.6/site-packages/django/template/base.py", line 194, in compile_nodelist
    return parser.parse()
  File "/home/luislaredov/.virtualenvs/django2/lib/python3.6/site-packages/django/template/base.py", line 477, in parse
    raise self.error(token, e)
  File "/home/luislaredov/.virtualenvs/django2/lib/python3.6/site-packages/django/template/base.py", line 475, in parse
    compiled_result = compile_func(self, token)
  File "/home/luislaredov/.virtualenvs/django2/lib/python3.6/site-packages/django/template/defaulttags.py", line 952, in do_if
    nodelist = parser.parse(('elif', 'else', 'endif'))
  File "/home/luislaredov/.virtualenvs/django2/lib/python3.6/site-packages/django/template/base.py", line 482, in parse
    self.unclosed_block_tag(parse_until)
  File "/home/luislaredov/.virtualenvs/django2/lib/python3.6/site-packages/django/template/base.py", line 543, in unclosed_block_tag
    raise self.error(token, msg)
django.template.exceptions.TemplateSyntaxError: Unclosed tag on line 31: 'if'. Looking for one of: elif, else, endif.
[17/Jun/2020 13:48:52] WARNING [django.request:228] Not Found: /favicon.ico
[17/Jun/2020 14:17:10] ERROR [django.request:228] Internal Server Error: /clase/editar/1/
Traceback (most recent call last):
  File "/home/luislaredov/.virtualenvs/django2/lib/python3.6/site-packages/django/core/handlers/exception.py", line 34, in inner
    response = get_response(request)
  File "/home/luislaredov/.virtualenvs/django2/lib/python3.6/site-packages/django/core/handlers/base.py", line 100, in _get_response
    resolver_match = resolver.resolve(request.path_info)
  File "/home/luislaredov/.virtualenvs/django2/lib/python3.6/site-packages/django/urls/resolvers.py", line 544, in resolve
    for pattern in self.url_patterns:
  File "/home/luislaredov/.virtualenvs/django2/lib/python3.6/site-packages/django/utils/functional.py", line 48, in __get__
    res = instance.__dict__[self.name] = self.func(instance)
  File "/home/luislaredov/.virtualenvs/django2/lib/python3.6/site-packages/django/urls/resolvers.py", line 588, in url_patterns
    patterns = getattr(self.urlconf_module, "urlpatterns", self.urlconf_module)
  File "/home/luislaredov/.virtualenvs/django2/lib/python3.6/site-packages/django/utils/functional.py", line 48, in __get__
    res = instance.__dict__[self.name] = self.func(instance)
  File "/home/luislaredov/.virtualenvs/django2/lib/python3.6/site-packages/django/urls/resolvers.py", line 581, in urlconf_module
    return import_module(self.urlconf_name)
  File "/home/luislaredov/.virtualenvs/django2/lib/python3.6/importlib/__init__.py", line 126, in import_module
    return _bootstrap._gcd_import(name[level:], package, level)
  File "<frozen importlib._bootstrap>", line 994, in _gcd_import
  File "<frozen importlib._bootstrap>", line 971, in _find_and_load
  File "<frozen importlib._bootstrap>", line 955, in _find_and_load_unlocked
  File "<frozen importlib._bootstrap>", line 665, in _load_unlocked
  File "<frozen importlib._bootstrap_external>", line 678, in exec_module
  File "<frozen importlib._bootstrap>", line 219, in _call_with_frames_removed
  File "/home/luislaredov/pixkal/pixkal/urls.py", line 20, in <module>
    path('pixkal2/', include('pixkal2.urls')),
  File "/home/luislaredov/.virtualenvs/django2/lib/python3.6/site-packages/django/urls/conf.py", line 34, in include
    urlconf_module = import_module(urlconf_module)
  File "/home/luislaredov/.virtualenvs/django2/lib/python3.6/importlib/__init__.py", line 126, in import_module
    return _bootstrap._gcd_import(name[level:], package, level)
  File "<frozen importlib._bootstrap>", line 994, in _gcd_import
  File "<frozen importlib._bootstrap>", line 971, in _find_and_load
  File "<frozen importlib._bootstrap>", line 955, in _find_and_load_unlocked
  File "<frozen importlib._bootstrap>", line 665, in _load_unlocked
  File "<frozen importlib._bootstrap_external>", line 678, in exec_module
  File "<frozen importlib._bootstrap>", line 219, in _call_with_frames_removed
  File "/home/luislaredov/pixkal/pixkal2/urls.py", line 7, in <module>
    from . import views
  File "/home/luislaredov/pixkal/pixkal2/views.py", line 675
    dash.url = 'clase/visualizar/' + clase.id + '/0/
                                                   ^
SyntaxError: EOL while scanning string literal
[17/Jun/2020 14:18:23] ERROR [django.request:228] Internal Server Error: /clase/activar/1/
Traceback (most recent call last):
  File "/home/luislaredov/pixkal/pixkal2/views.py", line 663, in ActivarClase
    dash = Dash.objects.get(id_actividad=clase_id,servicio='C')
  File "/home/luislaredov/.virtualenvs/django2/lib/python3.6/site-packages/django/db/models/manager.py", line 82, in manager_method
    return getattr(self.get_queryset(), name)(*args, **kwargs)
  File "/home/luislaredov/.virtualenvs/django2/lib/python3.6/site-packages/django/db/models/query.py", line 417, in get
    self.model._meta.object_name
pixkal2.models.Dash.DoesNotExist: Dash matching query does not exist.

During handling of the above exception, another exception occurred:

Traceback (most recent call last):
  File "/home/luislaredov/.virtualenvs/django2/lib/python3.6/site-packages/django/core/handlers/exception.py", line 34, in inner
    response = get_response(request)
  File "/home/luislaredov/.virtualenvs/django2/lib/python3.6/site-packages/django/core/handlers/base.py", line 115, in _get_response
    response = self.process_exception_by_middleware(e, request)
  File "/home/luislaredov/.virtualenvs/django2/lib/python3.6/site-packages/django/core/handlers/base.py", line 113, in _get_response
    response = wrapped_callback(request, *callback_args, **callback_kwargs)
  File "/home/luislaredov/pixkal/pixkal2/views.py", line 675, in ActivarClase
    dash.url = 'clase/visualizar/' + int(clase.id) + '/0/'
TypeError: must be str, not int
[17/Jun/2020 14:19:58] ERROR [django.request:228] Internal Server Error: /clase/activar/1/
Traceback (most recent call last):
  File "/home/luislaredov/pixkal/pixkal2/views.py", line 663, in ActivarClase
    dash = Dash.objects.get(id_actividad=int(clase_id),servicio='C')
  File "/home/luislaredov/.virtualenvs/django2/lib/python3.6/site-packages/django/db/models/manager.py", line 82, in manager_method
    return getattr(self.get_queryset(), name)(*args, **kwargs)
  File "/home/luislaredov/.virtualenvs/django2/lib/python3.6/site-packages/django/db/models/query.py", line 417, in get
    self.model._meta.object_name
pixkal2.models.Dash.DoesNotExist: Dash matching query does not exist.

During handling of the above exception, another exception occurred:

Traceback (most recent call last):
  File "/home/luislaredov/.virtualenvs/django2/lib/python3.6/site-packages/django/core/handlers/exception.py", line 34, in inner
    response = get_response(request)
  File "/home/luislaredov/.virtualenvs/django2/lib/python3.6/site-packages/django/core/handlers/base.py", line 115, in _get_response
    response = self.process_exception_by_middleware(e, request)
  File "/home/luislaredov/.virtualenvs/django2/lib/python3.6/site-packages/django/core/handlers/base.py", line 113, in _get_response
    response = wrapped_callback(request, *callback_args, **callback_kwargs)
  File "/home/luislaredov/pixkal/pixkal2/views.py", line 675, in ActivarClase
    dash.url = 'clase/visualizar/' + int(clase.id) + '/0/'
TypeError: must be str, not int
[17/Jun/2020 14:21:05] ERROR [django.request:228] Internal Server Error: /clase/activar/1/
Traceback (most recent call last):
  File "/home/luislaredov/pixkal/pixkal2/views.py", line 663, in ActivarClase
    dash = Dash.objects.get(id_actividad=str(clase_id),servicio='C')
  File "/home/luislaredov/.virtualenvs/django2/lib/python3.6/site-packages/django/db/models/manager.py", line 82, in manager_method
    return getattr(self.get_queryset(), name)(*args, **kwargs)
  File "/home/luislaredov/.virtualenvs/django2/lib/python3.6/site-packages/django/db/models/query.py", line 417, in get
    self.model._meta.object_name
pixkal2.models.Dash.DoesNotExist: Dash matching query does not exist.

During handling of the above exception, another exception occurred:

Traceback (most recent call last):
  File "/home/luislaredov/.virtualenvs/django2/lib/python3.6/site-packages/django/core/handlers/exception.py", line 34, in inner
    response = get_response(request)
  File "/home/luislaredov/.virtualenvs/django2/lib/python3.6/site-packages/django/core/handlers/base.py", line 115, in _get_response
    response = self.process_exception_by_middleware(e, request)
  File "/home/luislaredov/.virtualenvs/django2/lib/python3.6/site-packages/django/core/handlers/base.py", line 113, in _get_response
    response = wrapped_callback(request, *callback_args, **callback_kwargs)
  File "/home/luislaredov/pixkal/pixkal2/views.py", line 675, in ActivarClase
    dash.url = 'clase/visualizar/' + int(clase.id) + '/0/'
TypeError: must be str, not int
[17/Jun/2020 14:22:20] ERROR [django.request:228] Internal Server Error: /clase/activar/1/
Traceback (most recent call last):
  File "/home/luislaredov/pixkal/pixkal2/views.py", line 663, in ActivarClase
    dash = Dash.objects.get(id_actividad=clase_id,servicio='C')
  File "/home/luislaredov/.virtualenvs/django2/lib/python3.6/site-packages/django/db/models/manager.py", line 82, in manager_method
    return getattr(self.get_queryset(), name)(*args, **kwargs)
  File "/home/luislaredov/.virtualenvs/django2/lib/python3.6/site-packages/django/db/models/query.py", line 417, in get
    self.model._meta.object_name
pixkal2.models.Dash.DoesNotExist: Dash matching query does not exist.

During handling of the above exception, another exception occurred:

Traceback (most recent call last):
  File "/home/luislaredov/.virtualenvs/django2/lib/python3.6/site-packages/django/core/handlers/exception.py", line 34, in inner
    response = get_response(request)
  File "/home/luislaredov/.virtualenvs/django2/lib/python3.6/site-packages/django/core/handlers/base.py", line 115, in _get_response
    response = self.process_exception_by_middleware(e, request)
  File "/home/luislaredov/.virtualenvs/django2/lib/python3.6/site-packages/django/core/handlers/base.py", line 113, in _get_response
    response = wrapped_callback(request, *callback_args, **callback_kwargs)
  File "/home/luislaredov/pixkal/pixkal2/views.py", line 675, in ActivarClase
    dash.url = 'clase/visualizar/' + int(clase.id) + '/0/'
TypeError: must be str, not int
[17/Jun/2020 14:23:34] ERROR [django.request:228] Internal Server Error: /clase/activar/1/
Traceback (most recent call last):
  File "/home/luislaredov/pixkal/pixkal2/views.py", line 663, in ActivarClase
    dash = Dash.objects.get(id_actividad=str(clase_id),servicio='C')
  File "/home/luislaredov/.virtualenvs/django2/lib/python3.6/site-packages/django/db/models/manager.py", line 82, in manager_method
    return getattr(self.get_queryset(), name)(*args, **kwargs)
  File "/home/luislaredov/.virtualenvs/django2/lib/python3.6/site-packages/django/db/models/query.py", line 417, in get
    self.model._meta.object_name
pixkal2.models.Dash.DoesNotExist: Dash matching query does not exist.

During handling of the above exception, another exception occurred:

Traceback (most recent call last):
  File "/home/luislaredov/.virtualenvs/django2/lib/python3.6/site-packages/django/core/handlers/exception.py", line 34, in inner
    response = get_response(request)
  File "/home/luislaredov/.virtualenvs/django2/lib/python3.6/site-packages/django/core/handlers/base.py", line 115, in _get_response
    response = self.process_exception_by_middleware(e, request)
  File "/home/luislaredov/.virtualenvs/django2/lib/python3.6/site-packages/django/core/handlers/base.py", line 113, in _get_response
    response = wrapped_callback(request, *callback_args, **callback_kwargs)
  File "/home/luislaredov/pixkal/pixkal2/views.py", line 675, in ActivarClase
    dash.url = 'clase/visualizar/' + int(clase.id) + '/0/'
TypeError: must be str, not int
[17/Jun/2020 17:20:26] WARNING [django.request:228] Not Found: /favicon.ico
[17/Jun/2020 19:02:44] ERROR [django.request:228] Internal Server Error: /pixkal2/clase/editar/1/
Traceback (most recent call last):
  File "/home/luislaredov/.virtualenvs/django2/lib/python3.6/site-packages/django/core/handlers/exception.py", line 34, in inner
    response = get_response(request)
  File "/home/luislaredov/.virtualenvs/django2/lib/python3.6/site-packages/django/core/handlers/base.py", line 115, in _get_response
    response = self.process_exception_by_middleware(e, request)
  File "/home/luislaredov/.virtualenvs/django2/lib/python3.6/site-packages/django/core/handlers/base.py", line 113, in _get_response
    response = wrapped_callback(request, *callback_args, **callback_kwargs)
  File "/home/luislaredov/pixkal/pixkal2/views.py", line 656, in EditarClase
    dash.descripcion = clase.descripcion
AttributeError: 'Clase' object has no attribute 'descripcion'
[17/Jun/2020 19:03:52] ERROR [django.request:228] Internal Server Error: /pixkal2/clase/editar/1/
Traceback (most recent call last):
  File "/home/luislaredov/.virtualenvs/django2/lib/python3.6/site-packages/django/core/handlers/exception.py", line 34, in inner
    response = get_response(request)
  File "/home/luislaredov/.virtualenvs/django2/lib/python3.6/site-packages/django/core/handlers/base.py", line 115, in _get_response
    response = self.process_exception_by_middleware(e, request)
  File "/home/luislaredov/.virtualenvs/django2/lib/python3.6/site-packages/django/core/handlers/base.py", line 113, in _get_response
    response = wrapped_callback(request, *callback_args, **callback_kwargs)
  File "/home/luislaredov/pixkal/pixkal2/views.py", line 656, in EditarClase
    dash.imagen = clase.imagen
AttributeError: 'Clase' object has no attribute 'descripcion'
[17/Jun/2020 19:05:16] ERROR [django.request:228] Internal Server Error: /pixkal2/registrar/busqueda/
Traceback (most recent call last):
  File "/home/luislaredov/.virtualenvs/django2/lib/python3.6/site-packages/django/db/backends/mysql/base.py", line 74, in execute
    return self.cursor.execute(query, args)
  File "/home/luislaredov/.virtualenvs/django2/lib/python3.6/site-packages/MySQLdb/cursors.py", line 209, in execute
    res = self._query(query)
  File "/home/luislaredov/.virtualenvs/django2/lib/python3.6/site-packages/MySQLdb/cursors.py", line 315, in _query
    db.query(q)
  File "/home/luislaredov/.virtualenvs/django2/lib/python3.6/site-packages/MySQLdb/connections.py", line 239, in query
    _mysql.connection.query(self, query)
MySQLdb._exceptions.OperationalError: (1048, "Column 'numero_personas' cannot be null")

During handling of the above exception, another exception occurred:

Traceback (most recent call last):
  File "/home/luislaredov/.virtualenvs/django2/lib/python3.6/site-packages/django/core/handlers/exception.py", line 34, in inner
    response = get_response(request)
  File "/home/luislaredov/.virtualenvs/django2/lib/python3.6/site-packages/django/core/handlers/base.py", line 115, in _get_response
    response = self.process_exception_by_middleware(e, request)
  File "/home/luislaredov/.virtualenvs/django2/lib/python3.6/site-packages/django/core/handlers/base.py", line 113, in _get_response
    response = wrapped_callback(request, *callback_args, **callback_kwargs)
  File "/home/luislaredov/pixkal/pixkal2/views.py", line 227, in RegistrarBusqueda
    busqueda.save()
  File "/home/luislaredov/.virtualenvs/django2/lib/python3.6/site-packages/django/db/models/base.py", line 746, in save
    force_update=force_update, update_fields=update_fields)
  File "/home/luislaredov/.virtualenvs/django2/lib/python3.6/site-packages/django/db/models/base.py", line 784, in save_base
    force_update, using, update_fields,
  File "/home/luislaredov/.virtualenvs/django2/lib/python3.6/site-packages/django/db/models/base.py", line 887, in _save_table
    results = self._do_insert(cls._base_manager, using, fields, returning_fields, raw)
  File "/home/luislaredov/.virtualenvs/django2/lib/python3.6/site-packages/django/db/models/base.py", line 926, in _do_insert
    using=using, raw=raw,
  File "/home/luislaredov/.virtualenvs/django2/lib/python3.6/site-packages/django/db/models/manager.py", line 82, in manager_method
    return getattr(self.get_queryset(), name)(*args, **kwargs)
  File "/home/luislaredov/.virtualenvs/django2/lib/python3.6/site-packages/django/db/models/query.py", line 1204, in _insert
    return query.get_compiler(using=using).execute_sql(returning_fields)
  File "/home/luislaredov/.virtualenvs/django2/lib/python3.6/site-packages/django/db/models/sql/compiler.py", line 1391, in execute_sql
    cursor.execute(sql, params)
  File "/home/luislaredov/.virtualenvs/django2/lib/python3.6/site-packages/django/db/backends/utils.py", line 100, in execute
    return super().execute(sql, params)
  File "/home/luislaredov/.virtualenvs/django2/lib/python3.6/site-packages/django/db/backends/utils.py", line 68, in execute
    return self._execute_with_wrappers(sql, params, many=False, executor=self._execute)
  File "/home/luislaredov/.virtualenvs/django2/lib/python3.6/site-packages/django/db/backends/utils.py", line 77, in _execute_with_wrappers
    return executor(sql, params, many, context)
  File "/home/luislaredov/.virtualenvs/django2/lib/python3.6/site-packages/django/db/backends/utils.py", line 86, in _execute
    return self.cursor.execute(sql, params)
  File "/home/luislaredov/.virtualenvs/django2/lib/python3.6/site-packages/django/db/backends/mysql/base.py", line 79, in execute
    raise utils.IntegrityError(*tuple(e.args))
django.db.utils.IntegrityError: (1048, "Column 'numero_personas' cannot be null")
[17/Jun/2020 19:06:39] WARNING [django.request:228] Not Found: /pixkal2/registrar/busquedalugar/1/docs/images/favicon.ico
[17/Jun/2020 19:07:22] WARNING [django.request:228] Not Found: /registrar/busquedalugar/1/docs/images/favicon.ico
[17/Jun/2020 19:21:57] WARNING [django.request:228] Not Found: /media/
[17/Jun/2020 19:22:02] WARNING [django.request:228] Not Found: /pixkal2/dashboard/clase/visualizar/1/0/
[17/Jun/2020 19:23:31] WARNING [django.request:228] Not Found: /media/
[17/Jun/2020 19:26:17] WARNING [django.request:228] Not Found: /media/
[17/Jun/2020 19:34:34] WARNING [django.request:228] Not Found: /mapa/2/docs/images/favicon.ico
[17/Jun/2020 19:40:45] ERROR [django.request:228] Internal Server Error: /pixkal2/clase/registrar/
Traceback (most recent call last):
  File "/home/luislaredov/.virtualenvs/django2/lib/python3.6/site-packages/django/db/backends/mysql/base.py", line 74, in execute
    return self.cursor.execute(query, args)
  File "/home/luislaredov/.virtualenvs/django2/lib/python3.6/site-packages/MySQLdb/cursors.py", line 209, in execute
    res = self._query(query)
  File "/home/luislaredov/.virtualenvs/django2/lib/python3.6/site-packages/MySQLdb/cursors.py", line 315, in _query
    db.query(q)
  File "/home/luislaredov/.virtualenvs/django2/lib/python3.6/site-packages/MySQLdb/connections.py", line 239, in query
    _mysql.connection.query(self, query)
MySQLdb._exceptions.OperationalError: (1048, "Column 'avatar_id' cannot be null")

During handling of the above exception, another exception occurred:

Traceback (most recent call last):
  File "/home/luislaredov/.virtualenvs/django2/lib/python3.6/site-packages/django/core/handlers/exception.py", line 34, in inner
    response = get_response(request)
  File "/home/luislaredov/.virtualenvs/django2/lib/python3.6/site-packages/django/core/handlers/base.py", line 115, in _get_response
    response = self.process_exception_by_middleware(e, request)
  File "/home/luislaredov/.virtualenvs/django2/lib/python3.6/site-packages/django/core/handlers/base.py", line 113, in _get_response
    response = wrapped_callback(request, *callback_args, **callback_kwargs)
  File "/home/luislaredov/pixkal/pixkal2/views.py", line 474, in RegistrarClase
    clase.save()
  File "/home/luislaredov/.virtualenvs/django2/lib/python3.6/site-packages/django/db/models/base.py", line 746, in save
    force_update=force_update, update_fields=update_fields)
  File "/home/luislaredov/.virtualenvs/django2/lib/python3.6/site-packages/django/db/models/base.py", line 784, in save_base
    force_update, using, update_fields,
  File "/home/luislaredov/.virtualenvs/django2/lib/python3.6/site-packages/django/db/models/base.py", line 887, in _save_table
    results = self._do_insert(cls._base_manager, using, fields, returning_fields, raw)
  File "/home/luislaredov/.virtualenvs/django2/lib/python3.6/site-packages/django/db/models/base.py", line 926, in _do_insert
    using=using, raw=raw,
  File "/home/luislaredov/.virtualenvs/django2/lib/python3.6/site-packages/django/db/models/manager.py", line 82, in manager_method
    return getattr(self.get_queryset(), name)(*args, **kwargs)
  File "/home/luislaredov/.virtualenvs/django2/lib/python3.6/site-packages/django/db/models/query.py", line 1204, in _insert
    return query.get_compiler(using=using).execute_sql(returning_fields)
  File "/home/luislaredov/.virtualenvs/django2/lib/python3.6/site-packages/django/db/models/sql/compiler.py", line 1391, in execute_sql
    cursor.execute(sql, params)
  File "/home/luislaredov/.virtualenvs/django2/lib/python3.6/site-packages/django/db/backends/utils.py", line 100, in execute
    return super().execute(sql, params)
  File "/home/luislaredov/.virtualenvs/django2/lib/python3.6/site-packages/django/db/backends/utils.py", line 68, in execute
    return self._execute_with_wrappers(sql, params, many=False, executor=self._execute)
  File "/home/luislaredov/.virtualenvs/django2/lib/python3.6/site-packages/django/db/backends/utils.py", line 77, in _execute_with_wrappers
    return executor(sql, params, many, context)
  File "/home/luislaredov/.virtualenvs/django2/lib/python3.6/site-packages/django/db/backends/utils.py", line 86, in _execute
    return self.cursor.execute(sql, params)
  File "/home/luislaredov/.virtualenvs/django2/lib/python3.6/site-packages/django/db/backends/mysql/base.py", line 79, in execute
    raise utils.IntegrityError(*tuple(e.args))
django.db.utils.IntegrityError: (1048, "Column 'avatar_id' cannot be null")
[17/Jun/2020 19:49:17] WARNING [django.request:228] Not Found: /mapa/1/docs/images/favicon.ico
[18/Jun/2020 09:58:51] WARNING [django.request:228] Not Found: /favicon.ico
[18/Jun/2020 13:11:37] WARNING [django.request:228] Not Found: /favicon.ico
[18/Jun/2020 16:16:25] WARNING [django.request:228] Not Found: /favicon.ico
[18/Jun/2020 17:17:59] WARNING [django.request:228] Not Found: /favicon.ico
[19/Jun/2020 12:36:17] WARNING [django.request:228] Not Found: /favicon.ico
[19/Jun/2020 12:40:43] WARNING [django.request:228] Not Found: /pixkal2/registrar/busquedalugar/2/docs/images/favicon.ico
[19/Jun/2020 12:45:20] WARNING [django.request:228] Not Found: /registrar/busquedalugar/2/docs/images/favicon.ico
[19/Jun/2020 13:05:26] WARNING [django.request:228] Not Found: /busquedalugar/3/editar/docs/images/favicon.ico
[19/Jun/2020 13:15:43] WARNING [django.request:228] Not Found: /mapa/2/docs/images/favicon.ico
[19/Jun/2020 13:20:27] ERROR [django.request:228] Internal Server Error: /treasure/status/1/2
Traceback (most recent call last):
  File "/home/luislaredov/.virtualenvs/django2/lib/python3.6/site-packages/django/core/handlers/exception.py", line 34, in inner
    response = get_response(request)
  File "/home/luislaredov/.virtualenvs/django2/lib/python3.6/site-packages/django/core/handlers/base.py", line 115, in _get_response
    response = self.process_exception_by_middleware(e, request)
  File "/home/luislaredov/.virtualenvs/django2/lib/python3.6/site-packages/django/core/handlers/base.py", line 113, in _get_response
    response = wrapped_callback(request, *callback_args, **callback_kwargs)
  File "/home/luislaredov/pixkal/pixkal2/views.py", line 114, in StatusBusqueda
    busquedaparticipante = BusquedaParticipante.objects.get(busqueda=busqueda_id,usuario=request.user)
  File "/home/luislaredov/.virtualenvs/django2/lib/python3.6/site-packages/django/db/models/manager.py", line 82, in manager_method
    return getattr(self.get_queryset(), name)(*args, **kwargs)
  File "/home/luislaredov/.virtualenvs/django2/lib/python3.6/site-packages/django/db/models/query.py", line 417, in get
    self.model._meta.object_name
pixkal2.models.BusquedaParticipante.DoesNotExist: BusquedaParticipante matching query does not exist.
[19/Jun/2020 13:20:31] WARNING [django.request:228] Not Found: /treasure/status/1/2/
[19/Jun/2020 13:20:54] ERROR [django.request:228] Internal Server Error: /treasure/status/1/1
Traceback (most recent call last):
  File "/home/luislaredov/.virtualenvs/django2/lib/python3.6/site-packages/django/core/handlers/exception.py", line 34, in inner
    response = get_response(request)
  File "/home/luislaredov/.virtualenvs/django2/lib/python3.6/site-packages/django/core/handlers/base.py", line 115, in _get_response
    response = self.process_exception_by_middleware(e, request)
  File "/home/luislaredov/.virtualenvs/django2/lib/python3.6/site-packages/django/core/handlers/base.py", line 113, in _get_response
    response = wrapped_callback(request, *callback_args, **callback_kwargs)
  File "/home/luislaredov/pixkal/pixkal2/views.py", line 114, in StatusBusqueda
    busquedaparticipante = BusquedaParticipante.objects.get(busqueda=busqueda_id,usuario=request.user)
  File "/home/luislaredov/.virtualenvs/django2/lib/python3.6/site-packages/django/db/models/manager.py", line 82, in manager_method
    return getattr(self.get_queryset(), name)(*args, **kwargs)
  File "/home/luislaredov/.virtualenvs/django2/lib/python3.6/site-packages/django/db/models/query.py", line 417, in get
    self.model._meta.object_name
pixkal2.models.BusquedaParticipante.DoesNotExist: BusquedaParticipante matching query does not exist.
[19/Jun/2020 13:23:06] ERROR [django.request:228] Internal Server Error: /treasure/status/1/a2
Traceback (most recent call last):
  File "/home/luislaredov/.virtualenvs/django2/lib/python3.6/site-packages/django/core/handlers/exception.py", line 34, in inner
    response = get_response(request)
  File "/home/luislaredov/.virtualenvs/django2/lib/python3.6/site-packages/django/core/handlers/base.py", line 115, in _get_response
    response = self.process_exception_by_middleware(e, request)
  File "/home/luislaredov/.virtualenvs/django2/lib/python3.6/site-packages/django/core/handlers/base.py", line 113, in _get_response
    response = wrapped_callback(request, *callback_args, **callback_kwargs)
  File "/home/luislaredov/pixkal/pixkal2/views.py", line 114, in StatusBusqueda
    busquedaparticipante = BusquedaParticipante.objects.get(busqueda=busqueda_id,usuario=request.user)
  File "/home/luislaredov/.virtualenvs/django2/lib/python3.6/site-packages/django/db/models/manager.py", line 82, in manager_method
    return getattr(self.get_queryset(), name)(*args, **kwargs)
  File "/home/luislaredov/.virtualenvs/django2/lib/python3.6/site-packages/django/db/models/query.py", line 417, in get
    self.model._meta.object_name
pixkal2.models.BusquedaParticipante.DoesNotExist: BusquedaParticipante matching query does not exist.
[19/Jun/2020 13:23:17] ERROR [django.request:228] Internal Server Error: /treasure/status/1/1
Traceback (most recent call last):
  File "/home/luislaredov/.virtualenvs/django2/lib/python3.6/site-packages/django/core/handlers/exception.py", line 34, in inner
    response = get_response(request)
  File "/home/luislaredov/.virtualenvs/django2/lib/python3.6/site-packages/django/core/handlers/base.py", line 115, in _get_response
    response = self.process_exception_by_middleware(e, request)
  File "/home/luislaredov/.virtualenvs/django2/lib/python3.6/site-packages/django/core/handlers/base.py", line 113, in _get_response
    response = wrapped_callback(request, *callback_args, **callback_kwargs)
  File "/home/luislaredov/pixkal/pixkal2/views.py", line 114, in StatusBusqueda
    busquedaparticipante = BusquedaParticipante.objects.get(busqueda=busqueda_id,usuario=request.user)
  File "/home/luislaredov/.virtualenvs/django2/lib/python3.6/site-packages/django/db/models/manager.py", line 82, in manager_method
    return getattr(self.get_queryset(), name)(*args, **kwargs)
  File "/home/luislaredov/.virtualenvs/django2/lib/python3.6/site-packages/django/db/models/query.py", line 417, in get
    self.model._meta.object_name
pixkal2.models.BusquedaParticipante.DoesNotExist: BusquedaParticipante matching query does not exist.
[19/Jun/2020 13:23:22] ERROR [django.request:228] Internal Server Error: /treasure/status/1/2
Traceback (most recent call last):
  File "/home/luislaredov/.virtualenvs/django2/lib/python3.6/site-packages/django/core/handlers/exception.py", line 34, in inner
    response = get_response(request)
  File "/home/luislaredov/.virtualenvs/django2/lib/python3.6/site-packages/django/core/handlers/base.py", line 115, in _get_response
    response = self.process_exception_by_middleware(e, request)
  File "/home/luislaredov/.virtualenvs/django2/lib/python3.6/site-packages/django/core/handlers/base.py", line 113, in _get_response
    response = wrapped_callback(request, *callback_args, **callback_kwargs)
  File "/home/luislaredov/pixkal/pixkal2/views.py", line 114, in StatusBusqueda
    busquedaparticipante = BusquedaParticipante.objects.get(busqueda=busqueda_id,usuario=request.user)
  File "/home/luislaredov/.virtualenvs/django2/lib/python3.6/site-packages/django/db/models/manager.py", line 82, in manager_method
    return getattr(self.get_queryset(), name)(*args, **kwargs)
  File "/home/luislaredov/.virtualenvs/django2/lib/python3.6/site-packages/django/db/models/query.py", line 417, in get
    self.model._meta.object_name
pixkal2.models.BusquedaParticipante.DoesNotExist: BusquedaParticipante matching query does not exist.
[19/Jun/2020 13:23:25] ERROR [django.request:228] Internal Server Error: /treasure/status/1/3
Traceback (most recent call last):
  File "/home/luislaredov/.virtualenvs/django2/lib/python3.6/site-packages/django/core/handlers/exception.py", line 34, in inner
    response = get_response(request)
  File "/home/luislaredov/.virtualenvs/django2/lib/python3.6/site-packages/django/core/handlers/base.py", line 115, in _get_response
    response = self.process_exception_by_middleware(e, request)
  File "/home/luislaredov/.virtualenvs/django2/lib/python3.6/site-packages/django/core/handlers/base.py", line 113, in _get_response
    response = wrapped_callback(request, *callback_args, **callback_kwargs)
  File "/home/luislaredov/pixkal/pixkal2/views.py", line 114, in StatusBusqueda
    busquedaparticipante = BusquedaParticipante.objects.get(busqueda=busqueda_id,usuario=request.user)
  File "/home/luislaredov/.virtualenvs/django2/lib/python3.6/site-packages/django/db/models/manager.py", line 82, in manager_method
    return getattr(self.get_queryset(), name)(*args, **kwargs)
  File "/home/luislaredov/.virtualenvs/django2/lib/python3.6/site-packages/django/db/models/query.py", line 417, in get
    self.model._meta.object_name
pixkal2.models.BusquedaParticipante.DoesNotExist: BusquedaParticipante matching query does not exist.
[19/Jun/2020 13:23:28] ERROR [django.request:228] Internal Server Error: /treasure/status/1/4
Traceback (most recent call last):
  File "/home/luislaredov/.virtualenvs/django2/lib/python3.6/site-packages/django/core/handlers/exception.py", line 34, in inner
    response = get_response(request)
  File "/home/luislaredov/.virtualenvs/django2/lib/python3.6/site-packages/django/core/handlers/base.py", line 115, in _get_response
    response = self.process_exception_by_middleware(e, request)
  File "/home/luislaredov/.virtualenvs/django2/lib/python3.6/site-packages/django/core/handlers/base.py", line 113, in _get_response
    response = wrapped_callback(request, *callback_args, **callback_kwargs)
  File "/home/luislaredov/pixkal/pixkal2/views.py", line 114, in StatusBusqueda
    busquedaparticipante = BusquedaParticipante.objects.get(busqueda=busqueda_id,usuario=request.user)
  File "/home/luislaredov/.virtualenvs/django2/lib/python3.6/site-packages/django/db/models/manager.py", line 82, in manager_method
    return getattr(self.get_queryset(), name)(*args, **kwargs)
  File "/home/luislaredov/.virtualenvs/django2/lib/python3.6/site-packages/django/db/models/query.py", line 417, in get
    self.model._meta.object_name
pixkal2.models.BusquedaParticipante.DoesNotExist: BusquedaParticipante matching query does not exist.
[19/Jun/2020 13:35:31] WARNING [django.request:228] Not Found: /mapa/1/docs/images/favicon.ico
[19/Jun/2020 13:39:22] WARNING [django.request:228] Not Found: /mapa/3/docs/images/favicon.ico
[19/Jun/2020 13:39:55] WARNING [django.request:228] Not Found: /mapa/4/docs/images/favicon.ico
[19/Jun/2020 13:52:52] ERROR [django.request:228] Internal Server Error: /clase/visualizar/2/2/
Traceback (most recent call last):
  File "/home/luislaredov/.virtualenvs/django2/lib/python3.6/site-packages/django/core/handlers/exception.py", line 34, in inner
    response = get_response(request)
  File "/home/luislaredov/.virtualenvs/django2/lib/python3.6/site-packages/django/core/handlers/base.py", line 115, in _get_response
    response = self.process_exception_by_middleware(e, request)
  File "/home/luislaredov/.virtualenvs/django2/lib/python3.6/site-packages/django/core/handlers/base.py", line 113, in _get_response
    response = wrapped_callback(request, *callback_args, **callback_kwargs)
  File "/home/luislaredov/pixkal/pixkal2/views.py", line 662, in VisualizarClase
    item = items[int(orden)]
  File "/home/luislaredov/.virtualenvs/django2/lib/python3.6/site-packages/django/db/models/query.py", line 314, in __getitem__
    return qs._result_cache[0]
IndexError: list index out of range
[19/Jun/2020 13:54:10] ERROR [django.request:228] Internal Server Error: /clase/visualizar/2/2/
Traceback (most recent call last):
  File "/home/luislaredov/.virtualenvs/django2/lib/python3.6/site-packages/django/core/handlers/exception.py", line 34, in inner
    response = get_response(request)
  File "/home/luislaredov/.virtualenvs/django2/lib/python3.6/site-packages/django/core/handlers/base.py", line 115, in _get_response
    response = self.process_exception_by_middleware(e, request)
  File "/home/luislaredov/.virtualenvs/django2/lib/python3.6/site-packages/django/core/handlers/base.py", line 113, in _get_response
    response = wrapped_callback(request, *callback_args, **callback_kwargs)
  File "/home/luislaredov/pixkal/pixkal2/views.py", line 662, in VisualizarClase
    item = items[int(orden)]
  File "/home/luislaredov/.virtualenvs/django2/lib/python3.6/site-packages/django/db/models/query.py", line 314, in __getitem__
    return qs._result_cache[0]
IndexError: list index out of range
[19/Jun/2020 14:27:52] WARNING [django.request:228] Not Found: /favicon.ico
[19/Jun/2020 14:29:14] WARNING [django.request:228] Not Found: /mapa/4/docs/images/favicon.ico
[19/Jun/2020 14:44:26] WARNING [django.request:228] Not Found: /favicon.ico
[19/Jun/2020 14:45:14] WARNING [django.request:228] Not Found: /mapa/4/docs/images/favicon.ico
[20/Jun/2020 14:01:13] WARNING [django.request:228] Not Found: /favicon.ico
[22/Jun/2020 16:53:42] WARNING [django.request:228] Not Found: /favicon.ico
[22/Jun/2020 18:39:23] ERROR [django.request:228] Internal Server Error: /clase/item/avatar/actualizar/7/
Traceback (most recent call last):
  File "/home/luislaredov/.virtualenvs/django2/lib/python3.6/site-packages/django/core/handlers/exception.py", line 34, in inner
    response = get_response(request)
  File "/home/luislaredov/.virtualenvs/django2/lib/python3.6/site-packages/django/core/handlers/base.py", line 115, in _get_response
    response = self.process_exception_by_middleware(e, request)
  File "/home/luislaredov/.virtualenvs/django2/lib/python3.6/site-packages/django/core/handlers/base.py", line 113, in _get_response
    response = wrapped_callback(request, *callback_args, **callback_kwargs)
  File "/home/luislaredov/pixkal/pixkal2/views.py", line 689, in ActualizarItemImagenClase
    post.save()
  File "/home/luislaredov/.virtualenvs/django2/lib/python3.6/site-packages/django/db/models/base.py", line 746, in save
    force_update=force_update, update_fields=update_fields)
  File "/home/luislaredov/.virtualenvs/django2/lib/python3.6/site-packages/django/db/models/base.py", line 784, in save_base
    force_update, using, update_fields,
  File "/home/luislaredov/.virtualenvs/django2/lib/python3.6/site-packages/django/db/models/base.py", line 862, in _save_table
    for f in non_pks]
  File "/home/luislaredov/.virtualenvs/django2/lib/python3.6/site-packages/django/db/models/base.py", line 862, in <listcomp>
    for f in non_pks]
  File "/home/luislaredov/.virtualenvs/django2/lib/python3.6/site-packages/django/db/models/fields/files.py", line 288, in pre_save
    file.save(file.name, file.file, save=False)
  File "/home/luislaredov/.virtualenvs/django2/lib/python3.6/site-packages/django/db/models/fields/files.py", line 86, in save
    name = self.field.generate_filename(self.instance, name)
  File "/home/luislaredov/.virtualenvs/django2/lib/python3.6/site-packages/django/db/models/fields/files.py", line 303, in generate_filename
    filename = self.upload_to(instance, filename)
  File "/home/luislaredov/pixkal/pixkal2/models.py", line 34, in upload_location_a
    return 'avatares/%s.%s' % (instance.usuario.id, extension)
AttributeError: 'ClaseItem' object has no attribute 'usuario'
[22/Jun/2020 18:48:36] WARNING [django.request:228] Not Found: /favicon.ico
[22/Jun/2020 18:48:37] ERROR [django.request:228] Internal Server Error: /clase/visualizar/3/0/
Traceback (most recent call last):
  File "/home/luislaredov/.virtualenvs/django2/lib/python3.6/site-packages/django/template/base.py", line 469, in parse
    compile_func = self.tags[command]
KeyError: 'enif'

During handling of the above exception, another exception occurred:

Traceback (most recent call last):
  File "/home/luislaredov/.virtualenvs/django2/lib/python3.6/site-packages/django/core/handlers/exception.py", line 34, in inner
    response = get_response(request)
  File "/home/luislaredov/.virtualenvs/django2/lib/python3.6/site-packages/django/core/handlers/base.py", line 115, in _get_response
    response = self.process_exception_by_middleware(e, request)
  File "/home/luislaredov/.virtualenvs/django2/lib/python3.6/site-packages/django/core/handlers/base.py", line 113, in _get_response
    response = wrapped_callback(request, *callback_args, **callback_kwargs)
  File "/home/luislaredov/pixkal/pixkal2/views.py", line 679, in VisualizarClase
    return render(request, 'pixkal2/visualizarclase.html', {'item': item,'orden': orden,'clase_id':clase_id,'clase':principal_clase })
  File "/home/luislaredov/.virtualenvs/django2/lib/python3.6/site-packages/django/shortcuts.py", line 19, in render
    content = loader.render_to_string(template_name, context, request, using=using)
  File "/home/luislaredov/.virtualenvs/django2/lib/python3.6/site-packages/django/template/loader.py", line 61, in render_to_string
    template = get_template(template_name, using=using)
  File "/home/luislaredov/.virtualenvs/django2/lib/python3.6/site-packages/django/template/loader.py", line 15, in get_template
    return engine.get_template(template_name)
  File "/home/luislaredov/.virtualenvs/django2/lib/python3.6/site-packages/django/template/backends/django.py", line 34, in get_template
    return Template(self.engine.get_template(template_name), self)
  File "/home/luislaredov/.virtualenvs/django2/lib/python3.6/site-packages/django/template/engine.py", line 143, in get_template
    template, origin = self.find_template(template_name)
  File "/home/luislaredov/.virtualenvs/django2/lib/python3.6/site-packages/django/template/engine.py", line 125, in find_template
    template = loader.get_template(name, skip=skip)
  File "/home/luislaredov/.virtualenvs/django2/lib/python3.6/site-packages/django/template/loaders/base.py", line 30, in get_template
    contents, origin, origin.template_name, self.engine,
  File "/home/luislaredov/.virtualenvs/django2/lib/python3.6/site-packages/django/template/base.py", line 156, in __init__
    self.nodelist = self.compile_nodelist()
  File "/home/luislaredov/.virtualenvs/django2/lib/python3.6/site-packages/django/template/base.py", line 194, in compile_nodelist
    return parser.parse()
  File "/home/luislaredov/.virtualenvs/django2/lib/python3.6/site-packages/django/template/base.py", line 477, in parse
    raise self.error(token, e)
  File "/home/luislaredov/.virtualenvs/django2/lib/python3.6/site-packages/django/template/base.py", line 475, in parse
    compiled_result = compile_func(self, token)
  File "/home/luislaredov/.virtualenvs/django2/lib/python3.6/site-packages/django/template/defaulttags.py", line 952, in do_if
    nodelist = parser.parse(('elif', 'else', 'endif'))
  File "/home/luislaredov/.virtualenvs/django2/lib/python3.6/site-packages/django/template/base.py", line 477, in parse
    raise self.error(token, e)
  File "/home/luislaredov/.virtualenvs/django2/lib/python3.6/site-packages/django/template/base.py", line 475, in parse
    compiled_result = compile_func(self, token)
  File "/home/luislaredov/.virtualenvs/django2/lib/python3.6/site-packages/django/template/defaulttags.py", line 960, in do_if
    nodelist = parser.parse(('elif', 'else', 'endif'))
  File "/home/luislaredov/.virtualenvs/django2/lib/python3.6/site-packages/django/template/base.py", line 471, in parse
    self.invalid_block_tag(token, command, parse_until)
  File "/home/luislaredov/.virtualenvs/django2/lib/python3.6/site-packages/django/template/base.py", line 527, in invalid_block_tag
    get_text_list(["'%s'" % p for p in parse_until], 'or'),
django.template.exceptions.TemplateSyntaxError: Invalid block tag on line 51: 'enif', expected 'elif', 'else' or 'endif'. Did you forget to register or load this tag?
