[13/Jun/2020 15:49:40] ERROR [django.request:228] Internal Server Error: /clase/activar/2/
Traceback (most recent call last):
  File "/home/luislaredov/.virtualenvs/django2/lib/python3.6/site-packages/django/core/handlers/exception.py", line 34, in inner
    response = get_response(request)
  File "/home/luislaredov/.virtualenvs/django2/lib/python3.6/site-packages/django/core/handlers/base.py", line 115, in _get_response
    response = self.process_exception_by_middleware(e, request)
  File "/home/luislaredov/.virtualenvs/django2/lib/python3.6/site-packages/django/core/handlers/base.py", line 113, in _get_response
    response = wrapped_callback(request, *callback_args, **callback_kwargs)
TypeError: EditarClase() got an unexpected keyword argument 'clase_id'
[13/Jun/2020 15:59:16] WARNING [django.request:228] Not Found: /clase/imagen/actualizar/2/
[13/Jun/2020 16:27:38] ERROR [django.request:228] Internal Server Error: /clase/visualizar/1/0/
Traceback (most recent call last):
  File "/home/luislaredov/.virtualenvs/django2/lib/python3.6/site-packages/django/core/handlers/exception.py", line 34, in inner
    response = get_response(request)
  File "/home/luislaredov/.virtualenvs/django2/lib/python3.6/site-packages/django/core/handlers/base.py", line 115, in _get_response
    response = self.process_exception_by_middleware(e, request)
  File "/home/luislaredov/.virtualenvs/django2/lib/python3.6/site-packages/django/core/handlers/base.py", line 113, in _get_response
    response = wrapped_callback(request, *callback_args, **callback_kwargs)
TypeError: VisualizarClase() got multiple values for argument 'clase_id'
[13/Jun/2020 16:30:25] ERROR [django.request:228] Internal Server Error: /clase/visualizar/1/0/
Traceback (most recent call last):
  File "/home/luislaredov/.virtualenvs/django2/lib/python3.6/site-packages/django/core/handlers/exception.py", line 34, in inner
    response = get_response(request)
  File "/home/luislaredov/.virtualenvs/django2/lib/python3.6/site-packages/django/core/handlers/base.py", line 115, in _get_response
    response = self.process_exception_by_middleware(e, request)
  File "/home/luislaredov/.virtualenvs/django2/lib/python3.6/site-packages/django/core/handlers/base.py", line 113, in _get_response
    response = wrapped_callback(request, *callback_args, **callback_kwargs)
TypeError: VisualizarClase() got multiple values for argument 'clase_id'
[13/Jun/2020 16:32:56] ERROR [django.request:228] Internal Server Error: /clase/visualizar/1/0/
Traceback (most recent call last):
  File "/home/luislaredov/.virtualenvs/django2/lib/python3.6/site-packages/django/core/handlers/exception.py", line 34, in inner
    response = get_response(request)
  File "/home/luislaredov/.virtualenvs/django2/lib/python3.6/site-packages/django/core/handlers/base.py", line 115, in _get_response
    response = self.process_exception_by_middleware(e, request)
  File "/home/luislaredov/.virtualenvs/django2/lib/python3.6/site-packages/django/core/handlers/base.py", line 113, in _get_response
    response = wrapped_callback(request, *callback_args, **callback_kwargs)
TypeError: VisualizarClase() got multiple values for argument 'clase_id'
[13/Jun/2020 16:33:58] ERROR [django.request:228] Internal Server Error: /clase/visualizar/1/0/
Traceback (most recent call last):
  File "/home/luislaredov/.virtualenvs/django2/lib/python3.6/site-packages/django/core/handlers/exception.py", line 34, in inner
    response = get_response(request)
  File "/home/luislaredov/.virtualenvs/django2/lib/python3.6/site-packages/django/core/handlers/base.py", line 115, in _get_response
    response = self.process_exception_by_middleware(e, request)
  File "/home/luislaredov/.virtualenvs/django2/lib/python3.6/site-packages/django/core/handlers/base.py", line 113, in _get_response
    response = wrapped_callback(request, *callback_args, **callback_kwargs)
  File "/home/luislaredov/pixkal/pixkal2/views.py", line 665, in VisualizarClase
    items = ClaseItem.objects.get(clase=clase)
  File "/home/luislaredov/.virtualenvs/django2/lib/python3.6/site-packages/django/db/models/manager.py", line 82, in manager_method
    return getattr(self.get_queryset(), name)(*args, **kwargs)
  File "/home/luislaredov/.virtualenvs/django2/lib/python3.6/site-packages/django/db/models/query.py", line 417, in get
    self.model._meta.object_name
pixkal2.models.ClaseItem.DoesNotExist: ClaseItem matching query does not exist.
[13/Jun/2020 16:34:31] ERROR [django.request:228] Internal Server Error: /clase/visualizar/1/0/
Traceback (most recent call last):
  File "/home/luislaredov/.virtualenvs/django2/lib/python3.6/site-packages/django/core/handlers/exception.py", line 34, in inner
    response = get_response(request)
  File "/home/luislaredov/.virtualenvs/django2/lib/python3.6/site-packages/django/core/handlers/base.py", line 115, in _get_response
    response = self.process_exception_by_middleware(e, request)
  File "/home/luislaredov/.virtualenvs/django2/lib/python3.6/site-packages/django/core/handlers/base.py", line 113, in _get_response
    response = wrapped_callback(request, *callback_args, **callback_kwargs)
  File "/home/luislaredov/pixkal/pixkal2/views.py", line 664, in VisualizarClase
    items = ClaseItem.objects.get(clase=clase_id)
  File "/home/luislaredov/.virtualenvs/django2/lib/python3.6/site-packages/django/db/models/manager.py", line 82, in manager_method
    return getattr(self.get_queryset(), name)(*args, **kwargs)
  File "/home/luislaredov/.virtualenvs/django2/lib/python3.6/site-packages/django/db/models/query.py", line 417, in get
    self.model._meta.object_name
pixkal2.models.ClaseItem.DoesNotExist: ClaseItem matching query does not exist.
[13/Jun/2020 16:35:00] ERROR [django.request:228] Internal Server Error: /clase/visualizar/2/0/
Traceback (most recent call last):
  File "/home/luislaredov/.virtualenvs/django2/lib/python3.6/site-packages/django/core/handlers/exception.py", line 34, in inner
    response = get_response(request)
  File "/home/luislaredov/.virtualenvs/django2/lib/python3.6/site-packages/django/core/handlers/base.py", line 115, in _get_response
    response = self.process_exception_by_middleware(e, request)
  File "/home/luislaredov/.virtualenvs/django2/lib/python3.6/site-packages/django/core/handlers/base.py", line 113, in _get_response
    response = wrapped_callback(request, *callback_args, **callback_kwargs)
  File "/home/luislaredov/pixkal/pixkal2/views.py", line 664, in VisualizarClase
    items = ClaseItem.objects.get(clase=clase_id)
  File "/home/luislaredov/.virtualenvs/django2/lib/python3.6/site-packages/django/db/models/manager.py", line 82, in manager_method
    return getattr(self.get_queryset(), name)(*args, **kwargs)
  File "/home/luislaredov/.virtualenvs/django2/lib/python3.6/site-packages/django/db/models/query.py", line 422, in get
    num if not limit or num < limit else 'more than %s' % (limit - 1),
pixkal2.models.ClaseItem.MultipleObjectsReturned: get() returned more than one ClaseItem -- it returned 3!
[13/Jun/2020 16:35:56] ERROR [django.request:228] Internal Server Error: /clase/visualizar/2/0/
Traceback (most recent call last):
  File "/home/luislaredov/.virtualenvs/django2/lib/python3.6/site-packages/django/core/handlers/exception.py", line 34, in inner
    response = get_response(request)
  File "/home/luislaredov/.virtualenvs/django2/lib/python3.6/site-packages/django/core/handlers/base.py", line 115, in _get_response
    response = self.process_exception_by_middleware(e, request)
  File "/home/luislaredov/.virtualenvs/django2/lib/python3.6/site-packages/django/core/handlers/base.py", line 113, in _get_response
    response = wrapped_callback(request, *callback_args, **callback_kwargs)
  File "/home/luislaredov/pixkal/pixkal2/views.py", line 665, in VisualizarClase
    return render('pixkal2/visualizarclase.html', {'items': items })
  File "/home/luislaredov/.virtualenvs/django2/lib/python3.6/site-packages/django/shortcuts.py", line 19, in render
    content = loader.render_to_string(template_name, context, request, using=using)
  File "/home/luislaredov/.virtualenvs/django2/lib/python3.6/site-packages/django/template/loader.py", line 61, in render_to_string
    template = get_template(template_name, using=using)
  File "/home/luislaredov/.virtualenvs/django2/lib/python3.6/site-packages/django/template/loader.py", line 15, in get_template
    return engine.get_template(template_name)
  File "/home/luislaredov/.virtualenvs/django2/lib/python3.6/site-packages/django/template/backends/django.py", line 34, in get_template
    return Template(self.engine.get_template(template_name), self)
  File "/home/luislaredov/.virtualenvs/django2/lib/python3.6/site-packages/django/template/engine.py", line 143, in get_template
    template, origin = self.find_template(template_name)
  File "/home/luislaredov/.virtualenvs/django2/lib/python3.6/site-packages/django/template/engine.py", line 125, in find_template
    template = loader.get_template(name, skip=skip)
  File "/home/luislaredov/.virtualenvs/django2/lib/python3.6/site-packages/django/template/loaders/base.py", line 18, in get_template
    for origin in self.get_template_sources(template_name):
  File "/home/luislaredov/.virtualenvs/django2/lib/python3.6/site-packages/django/template/loaders/filesystem.py", line 36, in get_template_sources
    name = safe_join(template_dir, template_name)
  File "/home/luislaredov/.virtualenvs/django2/lib/python3.6/site-packages/django/utils/_os.py", line 17, in safe_join
    final_path = abspath(join(base, *paths))
  File "/home/luislaredov/.virtualenvs/django2/lib/python3.6/posixpath.py", line 94, in join
    genericpath._check_arg_types('join', a, *p)
  File "/home/luislaredov/.virtualenvs/django2/lib/python3.6/genericpath.py", line 149, in _check_arg_types
    (funcname, s.__class__.__name__)) from None
TypeError: join() argument must be str or bytes, not 'dict'
[13/Jun/2020 17:22:28] ERROR [django.request:228] Internal Server Error: /clase/visualizar/2/0/
Traceback (most recent call last):
  File "/home/luislaredov/.virtualenvs/django2/lib/python3.6/site-packages/django/core/handlers/exception.py", line 34, in inner
    response = get_response(request)
  File "/home/luislaredov/.virtualenvs/django2/lib/python3.6/site-packages/django/core/handlers/base.py", line 115, in _get_response
    response = self.process_exception_by_middleware(e, request)
  File "/home/luislaredov/.virtualenvs/django2/lib/python3.6/site-packages/django/core/handlers/base.py", line 113, in _get_response
    response = wrapped_callback(request, *callback_args, **callback_kwargs)
  File "/home/luislaredov/pixkal/pixkal2/views.py", line 665, in VisualizarClase
    item = items[orden]
  File "/home/luislaredov/.virtualenvs/django2/lib/python3.6/site-packages/django/db/models/query.py", line 288, in __getitem__
    % type(k).__name__
TypeError: QuerySet indices must be integers or slices, not str.
[13/Jun/2020 18:05:21] ERROR [django.request:228] Internal Server Error: /clase/visualizar/1/1/
Traceback (most recent call last):
  File "/home/luislaredov/.virtualenvs/django2/lib/python3.6/site-packages/django/core/handlers/exception.py", line 34, in inner
    response = get_response(request)
  File "/home/luislaredov/.virtualenvs/django2/lib/python3.6/site-packages/django/core/handlers/base.py", line 115, in _get_response
    response = self.process_exception_by_middleware(e, request)
  File "/home/luislaredov/.virtualenvs/django2/lib/python3.6/site-packages/django/core/handlers/base.py", line 113, in _get_response
    response = wrapped_callback(request, *callback_args, **callback_kwargs)
  File "/home/luislaredov/pixkal/pixkal2/views.py", line 665, in VisualizarClase
    item = items[int(orden)]
  File "/home/luislaredov/.virtualenvs/django2/lib/python3.6/site-packages/django/db/models/query.py", line 314, in __getitem__
    return qs._result_cache[0]
IndexError: list index out of range
[15/Jun/2020 17:51:46] WARNING [django.request:228] Not Found: /favicon.ico
[15/Jun/2020 17:51:57] ERROR [django.request:228] Internal Server Error: /admin/pixkal2/clase/
Traceback (most recent call last):
  File "/home/luislaredov/.virtualenvs/django2/lib/python3.6/site-packages/django/db/backends/utils.py", line 86, in _execute
    return self.cursor.execute(sql, params)
  File "/home/luislaredov/.virtualenvs/django2/lib/python3.6/site-packages/django/db/backends/mysql/base.py", line 74, in execute
    return self.cursor.execute(query, args)
  File "/home/luislaredov/.virtualenvs/django2/lib/python3.6/site-packages/MySQLdb/cursors.py", line 209, in execute
    res = self._query(query)
  File "/home/luislaredov/.virtualenvs/django2/lib/python3.6/site-packages/MySQLdb/cursors.py", line 315, in _query
    db.query(q)
  File "/home/luislaredov/.virtualenvs/django2/lib/python3.6/site-packages/MySQLdb/connections.py", line 239, in query
    _mysql.connection.query(self, query)
MySQLdb._exceptions.OperationalError: (1054, "Unknown column 'pixkal2_clase.bandera_marcador' in 'field list'")

The above exception was the direct cause of the following exception:

Traceback (most recent call last):
  File "/home/luislaredov/.virtualenvs/django2/lib/python3.6/site-packages/django/core/handlers/exception.py", line 34, in inner
    response = get_response(request)
  File "/home/luislaredov/.virtualenvs/django2/lib/python3.6/site-packages/django/core/handlers/base.py", line 115, in _get_response
    response = self.process_exception_by_middleware(e, request)
  File "/home/luislaredov/.virtualenvs/django2/lib/python3.6/site-packages/django/core/handlers/base.py", line 113, in _get_response
    response = wrapped_callback(request, *callback_args, **callback_kwargs)
  File "/home/luislaredov/.virtualenvs/django2/lib/python3.6/site-packages/django/contrib/admin/options.py", line 607, in wrapper
    return self.admin_site.admin_view(view)(*args, **kwargs)
  File "/home/luislaredov/.virtualenvs/django2/lib/python3.6/site-packages/django/utils/decorators.py", line 130, in _wrapped_view
    response = view_func(request, *args, **kwargs)
  File "/home/luislaredov/.virtualenvs/django2/lib/python3.6/site-packages/django/views/decorators/cache.py", line 44, in _wrapped_view_func
    response = view_func(request, *args, **kwargs)
  File "/home/luislaredov/.virtualenvs/django2/lib/python3.6/site-packages/django/contrib/admin/sites.py", line 231, in inner
    return view(request, *args, **kwargs)
  File "/home/luislaredov/.virtualenvs/django2/lib/python3.6/site-packages/django/utils/decorators.py", line 43, in _wrapper
    return bound_method(*args, **kwargs)
  File "/home/luislaredov/.virtualenvs/django2/lib/python3.6/site-packages/django/utils/decorators.py", line 130, in _wrapped_view
    response = view_func(request, *args, **kwargs)
  File "/home/luislaredov/.virtualenvs/django2/lib/python3.6/site-packages/django/contrib/admin/options.py", line 1796, in changelist_view
    'selection_note': _('0 of %(cnt)s selected') % {'cnt': len(cl.result_list)},
  File "/home/luislaredov/.virtualenvs/django2/lib/python3.6/site-packages/django/db/models/query.py", line 258, in __len__
    self._fetch_all()
  File "/home/luislaredov/.virtualenvs/django2/lib/python3.6/site-packages/django/db/models/query.py", line 1261, in _fetch_all
    self._result_cache = list(self._iterable_class(self))
  File "/home/luislaredov/.virtualenvs/django2/lib/python3.6/site-packages/django/db/models/query.py", line 57, in __iter__
    results = compiler.execute_sql(chunked_fetch=self.chunked_fetch, chunk_size=self.chunk_size)
  File "/home/luislaredov/.virtualenvs/django2/lib/python3.6/site-packages/django/db/models/sql/compiler.py", line 1151, in execute_sql
    cursor.execute(sql, params)
  File "/home/luislaredov/.virtualenvs/django2/lib/python3.6/site-packages/django/db/backends/utils.py", line 100, in execute
    return super().execute(sql, params)
  File "/home/luislaredov/.virtualenvs/django2/lib/python3.6/site-packages/django/db/backends/utils.py", line 68, in execute
    return self._execute_with_wrappers(sql, params, many=False, executor=self._execute)
  File "/home/luislaredov/.virtualenvs/django2/lib/python3.6/site-packages/django/db/backends/utils.py", line 77, in _execute_with_wrappers
    return executor(sql, params, many, context)
  File "/home/luislaredov/.virtualenvs/django2/lib/python3.6/site-packages/django/db/backends/utils.py", line 86, in _execute
    return self.cursor.execute(sql, params)
  File "/home/luislaredov/.virtualenvs/django2/lib/python3.6/site-packages/django/db/utils.py", line 90, in __exit__
    raise dj_exc_value.with_traceback(traceback) from exc_value
  File "/home/luislaredov/.virtualenvs/django2/lib/python3.6/site-packages/django/db/backends/utils.py", line 86, in _execute
    return self.cursor.execute(sql, params)
  File "/home/luislaredov/.virtualenvs/django2/lib/python3.6/site-packages/django/db/backends/mysql/base.py", line 74, in execute
    return self.cursor.execute(query, args)
  File "/home/luislaredov/.virtualenvs/django2/lib/python3.6/site-packages/MySQLdb/cursors.py", line 209, in execute
    res = self._query(query)
  File "/home/luislaredov/.virtualenvs/django2/lib/python3.6/site-packages/MySQLdb/cursors.py", line 315, in _query
    db.query(q)
  File "/home/luislaredov/.virtualenvs/django2/lib/python3.6/site-packages/MySQLdb/connections.py", line 239, in query
    _mysql.connection.query(self, query)
django.db.utils.OperationalError: (1054, "Unknown column 'pixkal2_clase.bandera_marcador' in 'field list'")
[15/Jun/2020 17:59:19] ERROR [django.request:228] Internal Server Error: /admin/pixkal2/clase/
Traceback (most recent call last):
  File "/home/luislaredov/.virtualenvs/django2/lib/python3.6/site-packages/django/db/backends/utils.py", line 86, in _execute
    return self.cursor.execute(sql, params)
  File "/home/luislaredov/.virtualenvs/django2/lib/python3.6/site-packages/django/db/backends/mysql/base.py", line 74, in execute
    return self.cursor.execute(query, args)
  File "/home/luislaredov/.virtualenvs/django2/lib/python3.6/site-packages/MySQLdb/cursors.py", line 209, in execute
    res = self._query(query)
  File "/home/luislaredov/.virtualenvs/django2/lib/python3.6/site-packages/MySQLdb/cursors.py", line 315, in _query
    db.query(q)
  File "/home/luislaredov/.virtualenvs/django2/lib/python3.6/site-packages/MySQLdb/connections.py", line 239, in query
    _mysql.connection.query(self, query)
MySQLdb._exceptions.OperationalError: (1054, "Unknown column 'pixkal2_clase.bandera_marcador' in 'field list'")

The above exception was the direct cause of the following exception:

Traceback (most recent call last):
  File "/home/luislaredov/.virtualenvs/django2/lib/python3.6/site-packages/django/core/handlers/exception.py", line 34, in inner
    response = get_response(request)
  File "/home/luislaredov/.virtualenvs/django2/lib/python3.6/site-packages/django/core/handlers/base.py", line 115, in _get_response
    response = self.process_exception_by_middleware(e, request)
  File "/home/luislaredov/.virtualenvs/django2/lib/python3.6/site-packages/django/core/handlers/base.py", line 113, in _get_response
    response = wrapped_callback(request, *callback_args, **callback_kwargs)
  File "/home/luislaredov/.virtualenvs/django2/lib/python3.6/site-packages/django/contrib/admin/options.py", line 607, in wrapper
    return self.admin_site.admin_view(view)(*args, **kwargs)
  File "/home/luislaredov/.virtualenvs/django2/lib/python3.6/site-packages/django/utils/decorators.py", line 130, in _wrapped_view
    response = view_func(request, *args, **kwargs)
  File "/home/luislaredov/.virtualenvs/django2/lib/python3.6/site-packages/django/views/decorators/cache.py", line 44, in _wrapped_view_func
    response = view_func(request, *args, **kwargs)
  File "/home/luislaredov/.virtualenvs/django2/lib/python3.6/site-packages/django/contrib/admin/sites.py", line 231, in inner
    return view(request, *args, **kwargs)
  File "/home/luislaredov/.virtualenvs/django2/lib/python3.6/site-packages/django/utils/decorators.py", line 43, in _wrapper
    return bound_method(*args, **kwargs)
  File "/home/luislaredov/.virtualenvs/django2/lib/python3.6/site-packages/django/utils/decorators.py", line 130, in _wrapped_view
    response = view_func(request, *args, **kwargs)
  File "/home/luislaredov/.virtualenvs/django2/lib/python3.6/site-packages/django/contrib/admin/options.py", line 1796, in changelist_view
    'selection_note': _('0 of %(cnt)s selected') % {'cnt': len(cl.result_list)},
  File "/home/luislaredov/.virtualenvs/django2/lib/python3.6/site-packages/django/db/models/query.py", line 258, in __len__
    self._fetch_all()
  File "/home/luislaredov/.virtualenvs/django2/lib/python3.6/site-packages/django/db/models/query.py", line 1261, in _fetch_all
    self._result_cache = list(self._iterable_class(self))
  File "/home/luislaredov/.virtualenvs/django2/lib/python3.6/site-packages/django/db/models/query.py", line 57, in __iter__
    results = compiler.execute_sql(chunked_fetch=self.chunked_fetch, chunk_size=self.chunk_size)
  File "/home/luislaredov/.virtualenvs/django2/lib/python3.6/site-packages/django/db/models/sql/compiler.py", line 1151, in execute_sql
    cursor.execute(sql, params)
  File "/home/luislaredov/.virtualenvs/django2/lib/python3.6/site-packages/django/db/backends/utils.py", line 100, in execute
    return super().execute(sql, params)
  File "/home/luislaredov/.virtualenvs/django2/lib/python3.6/site-packages/django/db/backends/utils.py", line 68, in execute
    return self._execute_with_wrappers(sql, params, many=False, executor=self._execute)
  File "/home/luislaredov/.virtualenvs/django2/lib/python3.6/site-packages/django/db/backends/utils.py", line 77, in _execute_with_wrappers
    return executor(sql, params, many, context)
  File "/home/luislaredov/.virtualenvs/django2/lib/python3.6/site-packages/django/db/backends/utils.py", line 86, in _execute
    return self.cursor.execute(sql, params)
  File "/home/luislaredov/.virtualenvs/django2/lib/python3.6/site-packages/django/db/utils.py", line 90, in __exit__
    raise dj_exc_value.with_traceback(traceback) from exc_value
  File "/home/luislaredov/.virtualenvs/django2/lib/python3.6/site-packages/django/db/backends/utils.py", line 86, in _execute
    return self.cursor.execute(sql, params)
  File "/home/luislaredov/.virtualenvs/django2/lib/python3.6/site-packages/django/db/backends/mysql/base.py", line 74, in execute
    return self.cursor.execute(query, args)
  File "/home/luislaredov/.virtualenvs/django2/lib/python3.6/site-packages/MySQLdb/cursors.py", line 209, in execute
    res = self._query(query)
  File "/home/luislaredov/.virtualenvs/django2/lib/python3.6/site-packages/MySQLdb/cursors.py", line 315, in _query
    db.query(q)
  File "/home/luislaredov/.virtualenvs/django2/lib/python3.6/site-packages/MySQLdb/connections.py", line 239, in query
    _mysql.connection.query(self, query)
django.db.utils.OperationalError: (1054, "Unknown column 'pixkal2_clase.bandera_marcador' in 'field list'")
[15/Jun/2020 19:14:28] WARNING [django.request:228] Not Found: /pixkal2/clase/registrar/
[15/Jun/2020 19:16:30] WARNING [django.request:228] Not Found: /pixkal2/clase/registrar/
[15/Jun/2020 19:18:40] WARNING [django.request:228] Not Found: /pixkal2/clase/registrar/
[15/Jun/2020 19:21:59] WARNING [django.request:228] Not Found: /pixkal2/clase/registrar/
[15/Jun/2020 19:23:09] WARNING [django.request:228] Not Found: /pixkal2/perfil/actualizar/
[15/Jun/2020 19:27:50] ERROR [django.request:228] Internal Server Error: /clase/visualizar/1/3/
Traceback (most recent call last):
  File "/home/luislaredov/.virtualenvs/django2/lib/python3.6/site-packages/django/core/handlers/exception.py", line 34, in inner
    response = get_response(request)
  File "/home/luislaredov/.virtualenvs/django2/lib/python3.6/site-packages/django/core/handlers/base.py", line 115, in _get_response
    response = self.process_exception_by_middleware(e, request)
  File "/home/luislaredov/.virtualenvs/django2/lib/python3.6/site-packages/django/core/handlers/base.py", line 113, in _get_response
    response = wrapped_callback(request, *callback_args, **callback_kwargs)
  File "/home/luislaredov/pixkal/pixkal2/views.py", line 665, in VisualizarClase
    item = items[int(orden)]
  File "/home/luislaredov/.virtualenvs/django2/lib/python3.6/site-packages/django/db/models/query.py", line 314, in __getitem__
    return qs._result_cache[0]
IndexError: list index out of range
[15/Jun/2020 19:32:04] ERROR [django.request:228] Internal Server Error: /clase/visualizar/1/0/
Traceback (most recent call last):
  File "/home/luislaredov/.virtualenvs/django2/lib/python3.6/site-packages/django/core/handlers/exception.py", line 34, in inner
    response = get_response(request)
  File "/home/luislaredov/.virtualenvs/django2/lib/python3.6/site-packages/django/core/handlers/base.py", line 115, in _get_response
    response = self.process_exception_by_middleware(e, request)
  File "/home/luislaredov/.virtualenvs/django2/lib/python3.6/site-packages/django/core/handlers/base.py", line 113, in _get_response
    response = wrapped_callback(request, *callback_args, **callback_kwargs)
  File "/home/luislaredov/pixkal/pixkal2/views.py", line 668, in VisualizarClase
    return render(request, 'pixkal2/visualizarclase.html', {'item': item,'orden': orden,'clase_id':clase_id,'clase':principal_clase })
  File "/home/luislaredov/.virtualenvs/django2/lib/python3.6/site-packages/django/shortcuts.py", line 19, in render
    content = loader.render_to_string(template_name, context, request, using=using)
  File "/home/luislaredov/.virtualenvs/django2/lib/python3.6/site-packages/django/template/loader.py", line 61, in render_to_string
    template = get_template(template_name, using=using)
  File "/home/luislaredov/.virtualenvs/django2/lib/python3.6/site-packages/django/template/loader.py", line 15, in get_template
    return engine.get_template(template_name)
  File "/home/luislaredov/.virtualenvs/django2/lib/python3.6/site-packages/django/template/backends/django.py", line 34, in get_template
    return Template(self.engine.get_template(template_name), self)
  File "/home/luislaredov/.virtualenvs/django2/lib/python3.6/site-packages/django/template/engine.py", line 143, in get_template
    template, origin = self.find_template(template_name)
  File "/home/luislaredov/.virtualenvs/django2/lib/python3.6/site-packages/django/template/engine.py", line 125, in find_template
    template = loader.get_template(name, skip=skip)
  File "/home/luislaredov/.virtualenvs/django2/lib/python3.6/site-packages/django/template/loaders/base.py", line 30, in get_template
    contents, origin, origin.template_name, self.engine,
  File "/home/luislaredov/.virtualenvs/django2/lib/python3.6/site-packages/django/template/base.py", line 156, in __init__
    self.nodelist = self.compile_nodelist()
  File "/home/luislaredov/.virtualenvs/django2/lib/python3.6/site-packages/django/template/base.py", line 194, in compile_nodelist
    return parser.parse()
  File "/home/luislaredov/.virtualenvs/django2/lib/python3.6/site-packages/django/template/base.py", line 477, in parse
    raise self.error(token, e)
  File "/home/luislaredov/.virtualenvs/django2/lib/python3.6/site-packages/django/template/base.py", line 475, in parse
    compiled_result = compile_func(self, token)
  File "/home/luislaredov/.virtualenvs/django2/lib/python3.6/site-packages/django/template/defaulttags.py", line 952, in do_if
    nodelist = parser.parse(('elif', 'else', 'endif'))
  File "/home/luislaredov/.virtualenvs/django2/lib/python3.6/site-packages/django/template/base.py", line 482, in parse
    self.unclosed_block_tag(parse_until)
  File "/home/luislaredov/.virtualenvs/django2/lib/python3.6/site-packages/django/template/base.py", line 543, in unclosed_block_tag
    raise self.error(token, msg)
django.template.exceptions.TemplateSyntaxError: Unclosed tag on line 31: 'if'. Looking for one of: elif, else, endif.
